<sdf version="1.4">
<model name="door">
  <pose>0 0 0 1.5708 0 0</pose>
  <static>false</static>
  
  <link name="door_frame">
    
      <inertial>
      <pose>0.525 1 0.05 0 0 0</pose>
        <mass>30.0</mass>
        <inertia> <!-- interias are tricky to compute -->
          <ixx>1</ixx>       
          <ixy>0.0</ixy>         
          <ixz>0.0</ixz>         
          <iyy>1</iyy>       
          <iyz>0.0</iyz>         
          <izz>1</izz>       
        </inertia>
      </inertial>
      
      <collision name="collision_frame">
        <pose>0 0 0 0 0 0</pose>
        <geometry>
          <mesh>
            <uri>model://door/meshes/frame.STL</uri>
	        <scale> 0.001 0.001 0.001 </scale>
          </mesh>
        </geometry>
      </collision>
      
      <visual name="visual_frame">
      <pose>0 0 0 0 0 0</pose>
        <geometry>
          <mesh>
            <uri>model://door/meshes/frame.STL</uri>
	        <scale> 0.001 0.001 0.001 </scale>
          </mesh>
        </geometry>
      </visual>
      
    </link>
    
    <link name="door_body">
    
      <inertial>
      <pose>0.525 1 0.05 0 0 0</pose>
        <mass>1.0</mass>
        <inertia> <!-- interias are tricky to compute -->
          <ixx>0.083</ixx>       
          <ixy>0.0</ixy>         
          <ixz>0.0</ixz>         
          <iyy>0.083</iyy>       
          <iyz>0.0</iyz>         
          <izz>0.083</izz>       
        </inertia>
      </inertial>
      
      <collision name="collision_door">
      <pose>0.525 0.995 0.05 0 0 0</pose>
        <geometry>
          <box>
            <size>0.9 1.99 0.03</size>
          </box>
        </geometry>
      </collision>
      
      <visual name="visual_door">
      <pose>0.525 0.995 0.05 0 0 0</pose>
        <geometry>
          <box>
            <size>0.9 1.99 0.03</size>
          </box>
        </geometry>
      </visual>
      
    </link>
    
    <joint name="door_hinge" type="revolute">
      <parent>door_frame</parent>
      <child>door_body</child>
      <pose>0.075 0 0.065 0 0 0</pose>
      <axis>
        <xyz>0 1 0</xyz>
        <dynamics>
            <damping>0.1</damping>
            <friction>0.1</friction>
        </dynamics>
      </axis>
    </joint>

    <link name="door_handle">
    
      <inertial>
      <pose>0.8 1 -0.005 3.1416 0 0</pose>
        <mass>1.0</mass>
        <inertia> <!-- interias are tricky to compute -->
          <ixx>1</ixx>       
          <ixy>0.0</ixy>         
          <ixz>0.0</ixz>         
          <iyy>1</iyy>       
          <iyz>0.0</iyz>         
          <izz>1</izz>       
        </inertia>
      </inertial>
      
      <collision name="collision_handle">
        <pose>0.8 1 -0.005 3.1416 0 0</pose>
        <geometry>
          <mesh>
            <uri>model://door/meshes/handle.STL</uri>
	        <scale> 0.001 0.001 0.001 </scale>
          </mesh>
        </geometry>
      </collision>
      
      <visual name="visual_handle">
      <pose>0.8 1 -0.005 3.1416 0 0</pose>
        <geometry>
          <mesh>
            <uri>model://door/meshes/handle.STL</uri>
	        <scale> 0.001 0.001 0.001 </scale>
          </mesh>
        </geometry>
      </visual>
      
    </link>

    <joint name="door_handle_joint" type="revolute">
      <parent>door_body</parent>
      <child>door_handle</child>
      <pose>0.075 0 0.065 0 0 0</pose>
      <axis>
        <xyz>0 1 0</xyz>
	<limit>
	  <lower>0.0</lower>
	  <upper>0.0</upper>
	</limit>
      </axis>
    </joint>
    
</model>
